#VRML_SIM R2019a utf8
WorldInfo {
  basicTimeStep 16
}
Viewpoint {
  orientation 0.1622183802561081 0.9452179460064233 0.28328118831733773 4.328501119951493
  position -2.613563061870265 1.9709617710384049 -1.1334706172483389
}
Background {
  skyColor [
    0.2 0.2 0.2
  ]
}
RectangleArena {
}
DEF GREEN_BOX Solid {
  translation -0.3927543170005528 0.05980379975048018 -0.30118904759521414
  rotation -7.36437331297923e-08 0.9999999999975308 2.2210804992003156e-06 0.0002529949521268222
  scale 1.2 1.2 1.2
  children [
    Shape {
      appearance PBRAppearance {
        baseColor 0 1 0
        roughness 0.2189099510000001
        metalness 0
      }
      geometry DEF BOX0 Box {
        size 0.1 0.1 0.1
      }
    }
  ]
  name "green box"
  boundingObject Shape {
    appearance PBRAppearance {
      roughness 1.1102230246251565e-16
      metalness 0
    }
    geometry USE BOX0
  }
  physics Physics {
  }
}
Robot {
  translation 0.19998673024188363 -0.0001063792894704721 0.10789026053923356
  rotation -0.029066114302370816 0.9994568391616576 0.015530217395445706 0.9813327182116481
  children [
    Transform {
      translation 0 0.0415 0
      children [
        Shape {
          appearance PBRAppearance {
            baseColor 0.0820075 0.364731 0.8
            roughness 1
            metalness 0
          }
          geometry DEF BODY Cylinder {
            height 0.08
            radius 0.045
          }
        }
      ]
    }
    HingeJoint {
      jointParameters HingeJointParameters {
        position 48.89599586690674
        axis -1 0 0
        anchor 0 0.025 0
      }
      device [
        RotationalMotor {
          name "left wheel motor"
          consumptionFactor 70
        }
        PositionSensor {
          name "left wheel sensor"
        }
      ]
      endPoint Solid {
        translation -0.04499999999999999 0.025 0
        rotation -1 0 0 6.212214023829217
        children [
          DEF WHEEL Transform {
            rotation 0 0 1 1.57
            children [
              Shape {
                appearance PBRAppearance {
                  baseColor 1 0 0
                  roughness 1
                  metalness 0
                }
                geometry Cylinder {
                  height 0.01
                  radius 0.025
                }
              }
            ]
          }
        ]
        name "left wheel"
        boundingObject USE WHEEL
        physics DEF PHYSICS_WHEEL Physics {
          density -1
          mass 0.05
        }
      }
    }
    HingeJoint {
      jointParameters HingeJointParameters {
        position 48.89599578953901
        axis -1 0 0
        anchor 0 0.025 0
      }
      device [
        RotationalMotor {
          name "right wheel motor"
          consumptionFactor 70
        }
        PositionSensor {
          name "right wheel sensor"
        }
      ]
      endPoint Solid {
        translation 0.04499999999999999 0.025 0
        rotation 1 0 0 5.956836667897685
        children [
          USE WHEEL
        ]
        name "right wheel"
        boundingObject USE WHEEL
        physics USE PHYSICS_WHEEL
      }
    }
    DistanceSensor {
      translation -0.02 0.063 -0.042
      rotation 0 1 0 2.07
      children [
        DEF SENSOR Transform {
          rotation 0 0 1 1.57
          children [
            Shape {
              appearance PBRAppearance {
                baseColor 0.975691 0.981481 0.0252992
                roughness 1
                metalness 0
              }
              geometry Cylinder {
                height 0.004
                radius 0.008
              }
            }
          ]
        }
      ]
      name "ds0"
      lookupTable [
        0 1024 0
        0.05 1024 0
        0.15 0 0
      ]
      numberOfRays 2
      aperture 1
    }
    DistanceSensor {
      translation 0.02 0.063 -0.042
      rotation 0 1 0 1.07
      children [
        USE SENSOR
      ]
      name "ds1"
      lookupTable [
        0 1024 0
        0.05 1024 0
        0.15 0 0
      ]
      numberOfRays 2
      aperture 1
    }
    DEF SMILE Transform {
      translation 0 0.025 -0.036
      rotation 0.7745972408364944 0.44721228048294853 0.4472139204829502 1.8234794
      children [
        Shape {
          appearance PBRAppearance {
            baseColor 0.721569 0.290196 0.290196
            roughness 1
            metalness 0
          }
          geometry Cylinder {
            height 0.018
            radius 0.009
            subdivision 3
          }
        }
      ]
    }
    Camera {
      translation 0 0.0915 -0.04
      rotation 0 0 -1 0
      children [
        Transform {
          translation 0 0 0.015
          rotation 1 0 0 1.57
          children [
            Shape {
              appearance PBRAppearance {
                roughness 1
                metalness 0
              }
              geometry Cylinder {
                height 0.03
                radius 0.01
              }
            }
          ]
        }
      ]
      fieldOfView 1.047
      width 80
      height 60
      antiAliasing TRUE
      noise 0.04
    }
  ]
  name "MyBot"
  boundingObject Transform {
    translation 0 0.0415 0
    children [
      USE BODY
    ]
  }
  physics Physics {
    density -1
    mass 0.5
  }
  controller "goforwardcamera"
}
DirectionalLight {
  direction -0.33 -1 0.5
  intensity 2.3
  castShadows TRUE
}
